<?xml version="1.0" ?><robot name="fr3"><link name="fr3_link0"><visual name="fr3_link0_visual"><geometry><mesh filename="package://franka_description/meshes/robot_arms/fr3/visual/link0.dae"/></geometry></visual><collision name="fr3_link0_collision"><geometry><mesh filename="package://franka_description/meshes/robot_arms/fr3/collision/link0.stl"/></geometry></collision><inertial><origin rpy="0 0 0" xyz="-0.0172 0.0004 0.0745"/><mass value="2.3966"/><inertia ixx="0.009" ixy="0.0" ixz="0.002" iyy="0.0115" iyz="0.0" izz="0.0085"/></inertial></link><link name="fr3_link1"><visual name="fr3_link1_visual"><geometry><mesh filename="package://franka_description/meshes/robot_arms/fr3/visual/link1.dae"/></geometry></visual><collision name="fr3_link1_collision"><geometry><mesh filename="package://franka_description/meshes/robot_arms/fr3/collision/link1.stl"/></geometry></collision><inertial><origin rpy="0 0 0" xyz="0.0000004128 -0.0181251324 -0.0386035970"/><mass value="2.9274653454"/><inertia ixx="0.023927316485107913" ixy="1.3317903455714081e-05" ixz="-0.00011404774918616684" iyy="0.0224821613275756" iyz="-0.0019950320628240115" izz="0.006350098258530016"/></inertial></link><joint name="fr3_joint1" type="revolute"><origin rpy="0 0 0" xyz="0 0 0.333"/><parent link="fr3_link0"/><child link="fr3_link1"/><axis xyz="0 0 1"/><limit effort="87.0" lower="-2.7437" upper="2.7437" velocity="2.62"/><safety_controller k_position="100.0" k_velocity="40.0" soft_lower_limit="-2.7437" soft_upper_limit="2.7437"/><dynamics D="1" K="7000" damping="0.003" friction="0.2" mu_coulomb="0" mu_viscous="16"/></joint><link name="fr3_link2"><visual name="fr3_link2_visual"><geometry><mesh filename="package://franka_description/meshes/robot_arms/fr3/visual/link2.dae"/></geometry></visual><collision name="fr3_link2_collision"><geometry><mesh filename="package://franka_description/meshes/robot_arms/fr3/collision/link2.stl"/></geometry></collision><inertial><origin rpy="0 0 0" xyz="0.0031828864 -0.0743221644 0.0088146084"/><mass value="2.9355370338"/><inertia ixx="0.041938946257609425" ixy="0.00020257331521090626" ixz="0.004077784227179924" iyy="0.02514514885014724" iyz="-0.0042252158006570156" izz="0.06170214472888839"/></inertial></link><joint name="fr3_joint2" type="revolute"><origin rpy="-1.570796326794897 0 0" xyz="0 0 0"/><parent link="fr3_link1"/><child link="fr3_link2"/><axis xyz="0 0 1"/><limit effort="87.0" lower="-1.7837" upper="1.7837" velocity="2.62"/><safety_controller k_position="100.0" k_velocity="40.0" soft_lower_limit="-1.7837" soft_upper_limit="1.7837"/><dynamics D="1" K="7000" damping="0.003" friction="0.2" mu_coulomb="0" mu_viscous="16"/></joint><link name="fr3_link3"><visual name="fr3_link3_visual"><geometry><mesh filename="package://franka_description/meshes/robot_arms/fr3/visual/link3.dae"/></geometry></visual><collision name="fr3_link3_collision"><geometry><mesh filename="package://franka_description/meshes/robot_arms/fr3/collision/link3.stl"/></geometry></collision><inertial><origin rpy="0 0 0" xyz="0.0407015686 -0.0048200565 -0.0289730823"/><mass value="2.2449013699"/><inertia ixx="0.02410142547240885" ixy="0.002404694559042109" ixz="-0.002856269270114313" iyy="0.01974053266708178" iyz="-0.002104212683891874" izz="0.019044494482244823"/></inertial></link><joint name="fr3_joint3" type="revolute"><origin rpy="1.570796326794897 0 0" xyz="0 -0.316 0"/><parent link="fr3_link2"/><child link="fr3_link3"/><axis xyz="0 0 1"/><limit effort="87.0" lower="-2.9007" upper="2.9007" velocity="2.62"/><safety_controller k_position="100.0" k_velocity="40.0" soft_lower_limit="-2.9007" soft_upper_limit="2.9007"/><dynamics D="1" K="7000" damping="0.003" friction="0.2" mu_coulomb="0" mu_viscous="16"/></joint><link name="fr3_link4"><visual name="fr3_link4_visual"><geometry><mesh filename="package://franka_description/meshes/robot_arms/fr3/visual/link4.dae"/></geometry></visual><collision name="fr3_link4_collision"><geometry><mesh filename="package://franka_description/meshes/robot_arms/fr3/collision/link4.stl"/></geometry></collision><inertial><origin rpy="0 0 0" xyz="-0.0459100965 0.0630492960 -0.0085187868"/><mass value="2.6155955791"/><inertia ixx="0.03452998321913202" ixy="0.01322552265982813" ixz="0.01015142998484113" iyy="0.028881621933049058" iyz="-0.0009762833870704552" izz="0.04125471171146641"/></inertial></link><joint name="fr3_joint4" type="revolute"><origin rpy="1.570796326794897 0 0" xyz="0.0825 0 0"/><parent link="fr3_link3"/><child link="fr3_link4"/><axis xyz="0 0 1"/><limit effort="87.0" lower="-3.0421" upper="-0.1518" velocity="2.62"/><safety_controller k_position="100.0" k_velocity="40.0" soft_lower_limit="-3.0421" soft_upper_limit="-0.1518"/><dynamics D="1" K="7000" damping="0.003" friction="0.2" mu_coulomb="0" mu_viscous="16"/></joint><link name="fr3_link5"><visual name="fr3_link5_visual"><geometry><mesh filename="package://franka_description/meshes/robot_arms/fr3/visual/link5.dae"/></geometry></visual><collision name="fr3_link5_collision"><geometry><mesh filename="package://franka_description/meshes/robot_arms/fr3/collision/link5.stl"/></geometry></collision><inertial><origin rpy="0 0 0" xyz="-0.0016039605 0.0292536262 -0.0972965990"/><mass value="2.3271207594"/><inertia ixx="0.051610278463662895" ixy="-0.005715173387783472" ixz="-0.0035673167625872135" iyy="0.04787729713371481" iyz="0.010673985108535986" izz="0.016423625579357254"/></inertial></link><joint name="fr3_joint5" type="revolute"><origin rpy="-1.570796326794897 0 0" xyz="-0.0825 0.384 0"/><parent link="fr3_link4"/><child link="fr3_link5"/><axis xyz="0 0 1"/><limit effort="12.0" lower="-2.8065" upper="2.8065" velocity="5.26"/><safety_controller k_position="100.0" k_velocity="40.0" soft_lower_limit="-2.8065" soft_upper_limit="2.8065"/><dynamics D="1" K="7000" damping="0.003" friction="0.2" mu_coulomb="0" mu_viscous="16"/></joint><link name="fr3_link6"><visual name="fr3_link6_visual"><geometry><mesh filename="package://franka_description/meshes/robot_arms/fr3/visual/link6.dae"/></geometry></visual><collision name="fr3_link6_collision"><geometry><mesh filename="package://franka_description/meshes/robot_arms/fr3/collision/link6.stl"/></geometry></collision><inertial><origin rpy="0 0 0" xyz="0.0597131221 -0.0410294666 -0.0101692726"/><mass value="1.8170376524"/><inertia ixx="0.005412333594383447" ixy="0.006193456360285834" ixz="0.0014219289306117652" iyy="0.014058329545509979" iyz="-0.0013140753741120031" izz="0.016080817924212554"/></inertial></link><joint name="fr3_joint6" type="revolute"><origin rpy="1.570796326794897 0 0" xyz="0 0 0"/><parent link="fr3_link5"/><child link="fr3_link6"/><axis xyz="0 0 1"/><limit effort="12.0" lower="0.5445" upper="4.5169" velocity="4.18"/><safety_controller k_position="100.0" k_velocity="40.0" soft_lower_limit="0.5445" soft_upper_limit="4.5169"/><dynamics D="1" K="7000" damping="0.003" friction="0.2" mu_coulomb="0" mu_viscous="16"/></joint><link name="fr3_link7"><visual name="fr3_link7_visual"><geometry><mesh filename="package://franka_description/meshes/robot_arms/fr3/visual/link7.dae"/></geometry></visual><collision name="fr3_link7_collision"><geometry><mesh filename="package://franka_description/meshes/robot_arms/fr3/collision/link7.stl"/></geometry></collision><inertial><origin rpy="0 0 0" xyz="0.0045225817 0.0086261921 -0.0161633251"/><mass value="0.6271432862"/><inertia ixx="0.00021092389150104718" ixy="-2.433299114461931e-05" ixz="4.564480393778983e-05" iyy="0.00017718568002411474" iyz="8.744070223226438e-05" izz="5.993190599659971e-05"/></inertial></link><joint name="fr3_joint7" type="revolute"><origin rpy="1.570796326794897 0 0" xyz="0.088 0 0"/><parent link="fr3_link6"/><child link="fr3_link7"/><axis xyz="0 0 1"/><limit effort="12.0" lower="-3.0159" upper="3.0159" velocity="5.26"/><safety_controller k_position="100.0" k_velocity="40.0" soft_lower_limit="-3.0159" soft_upper_limit="3.0159"/><dynamics D="1" K="7000" damping="0.003" friction="0.2" mu_coulomb="0" mu_viscous="16"/></joint><link name="fr3_link8"/><joint name="fr3_joint8" type="fixed"><origin rpy="0 0 0" xyz="0 0 0.107"/><parent link="fr3_link7"/><child link="fr3_link8"/></joint><joint name="fr3_hand_joint" type="fixed"><parent link="fr3_link8"/><child link="fr3_hand"/><origin rpy="0 0 -0.7853981633974483" xyz="0 0 0"/></joint><link name="fr3_hand"><visual name="fr3_hand_visual"><geometry><mesh filename="package://franka_description/meshes/robot_ee/franka_hand_white/visual/hand.dae"/></geometry></visual><collision name="fr3_hand_collision"><geometry><mesh filename="package://franka_description/meshes/robot_ee/franka_hand_white/collision/hand.stl"/></geometry></collision><inertial><origin rpy="0 0 0" xyz="-0.01 0 0.03"/><mass value="0.73"/><inertia ixx="0.001" ixy="0" ixz="0" iyy="0.0025" iyz="0" izz="0.0017"/></inertial></link><link name="fr3_hand_tcp"/><joint name="fr3_hand_tcp_joint" type="fixed"><origin rpy="0 0 0" xyz="0 0 0.1034"/><parent link="fr3_hand"/><child link="fr3_hand_tcp"/></joint><link name="fr3_leftfinger"><visual name="fr3_leftfinger_visual"><geometry><mesh filename="package://franka_description/meshes/robot_ee/franka_hand_white/visual/finger.dae"/></geometry></visual><collision><origin rpy="0 0 0" xyz="0 18.5e-3 11e-3"/><geometry><box size="22e-3 15e-3 20e-3"/></geometry></collision><collision><origin rpy="0 0 0" xyz="0 6.8e-3 2.2e-3"/><geometry><box size="22e-3 8.8e-3 3.8e-3"/></geometry></collision><collision><origin rpy="0.5235987755982988 0 0" xyz="0 15.9e-3 28.35e-3"/><geometry><box size="17.5e-3 7e-3 23.5e-3"/></geometry></collision><collision><origin rpy="0 0 0" xyz="0 7.58e-3 45.25e-3"/><geometry><box size="17.5e-3 15.2e-3 18.5e-3"/></geometry></collision><inertial><origin rpy="0 0 0" xyz="0 0 0"/><mass value="0.015"/><inertia ixx="2.3749999999999997e-06" ixy="0" ixz="0" iyy="2.3749999999999997e-06" iyz="0" izz="7.5e-07"/></inertial></link><link name="fr3_rightfinger"><visual name="fr3_rightfinger_visual"><origin rpy="0 0 3.141592653589793" xyz="0 0 0"/><geometry><mesh filename="package://franka_description/meshes/robot_ee/franka_hand_white/visual/finger.dae"/></geometry></visual><collision><origin rpy="0 0 0" xyz="0 -18.5e-3 11e-3"/><geometry><box size="22e-3 15e-3 20e-3"/></geometry></collision><collision><origin rpy="0 0 0" xyz="0 -6.8e-3 2.2e-3"/><geometry><box size="22e-3 8.8e-3 3.8e-3"/></geometry></collision><collision><origin rpy="-0.5235987755982988 0 0" xyz="0 -15.9e-3 28.35e-3"/><geometry><box size="17.5e-3 7e-3 23.5e-3"/></geometry></collision><collision><origin rpy="0 0 0" xyz="0 -7.58e-3 45.25e-3"/><geometry><box size="17.5e-3 15.2e-3 18.5e-3"/></geometry></collision><inertial><origin rpy="0 0 0" xyz="0 0 0"/><mass value="0.015"/><inertia ixx="2.3749999999999997e-06" ixy="0" ixz="0" iyy="2.3749999999999997e-06" iyz="0" izz="7.5e-07"/></inertial></link><joint name="fr3_finger_joint1" type="prismatic"><parent link="fr3_hand"/><child link="fr3_leftfinger"/><origin rpy="0 0 0" xyz="0 0 0.0584"/><axis xyz="0 1 0"/><limit effort="100" lower="0.0" upper="0.04" velocity="0.2"/><dynamics damping="0.3"/></joint><joint name="fr3_finger_joint2" type="prismatic"><parent link="fr3_hand"/><child link="fr3_rightfinger"/><origin rpy="0 0 0" xyz="0 0 0.0584"/><axis xyz="0 -1 0"/><limit effort="100" lower="0.0" upper="0.04" velocity="0.2"/><mimic joint="fr3_finger_joint1"/><dynamics damping="0.3"/></joint><link name="world"/><joint name="world_joint" type="fixed"><origin rpy="0 0 0" xyz="0 0 0"/><parent link="world"/><child link="fr3_link0"/></joint><gazebo reference="fr3_joint1"><provideFeedback>true</provideFeedback></gazebo><transmission name="fr3_joint1_transmission"><type>transmission_interface/SimpleTransmission</type><joint name="fr3_joint1"><hardwareInterface>hardware_interface/PositionJointInterface</hardwareInterface></joint><actuator name="fr3_joint1_motor"><hardwareInterface>hardware_interface/PositionJointInterface</hardwareInterface></actuator></transmission><gazebo reference="fr3_joint2"><provideFeedback>true</provideFeedback></gazebo><transmission name="fr3_joint2_transmission"><type>transmission_interface/SimpleTransmission</type><joint name="fr3_joint2"><hardwareInterface>hardware_interface/PositionJointInterface</hardwareInterface></joint><actuator name="fr3_joint2_motor"><hardwareInterface>hardware_interface/PositionJointInterface</hardwareInterface></actuator></transmission><gazebo reference="fr3_joint3"><provideFeedback>true</provideFeedback></gazebo><transmission name="fr3_joint3_transmission"><type>transmission_interface/SimpleTransmission</type><joint name="fr3_joint3"><hardwareInterface>hardware_interface/PositionJointInterface</hardwareInterface></joint><actuator name="fr3_joint3_motor"><hardwareInterface>hardware_interface/PositionJointInterface</hardwareInterface></actuator></transmission><gazebo reference="fr3_joint4"><provideFeedback>true</provideFeedback></gazebo><transmission name="fr3_joint4_transmission"><type>transmission_interface/SimpleTransmission</type><joint name="fr3_joint4"><hardwareInterface>hardware_interface/PositionJointInterface</hardwareInterface></joint><actuator name="fr3_joint4_motor"><hardwareInterface>hardware_interface/PositionJointInterface</hardwareInterface></actuator></transmission><gazebo reference="fr3_joint5"><provideFeedback>true</provideFeedback></gazebo><transmission name="fr3_joint5_transmission"><type>transmission_interface/SimpleTransmission</type><joint name="fr3_joint5"><hardwareInterface>hardware_interface/PositionJointInterface</hardwareInterface></joint><actuator name="fr3_joint5_motor"><hardwareInterface>hardware_interface/PositionJointInterface</hardwareInterface></actuator></transmission><gazebo reference="fr3_joint6"><provideFeedback>true</provideFeedback></gazebo><transmission name="fr3_joint6_transmission"><type>transmission_interface/SimpleTransmission</type><joint name="fr3_joint6"><hardwareInterface>hardware_interface/PositionJointInterface</hardwareInterface></joint><actuator name="fr3_joint6_motor"><hardwareInterface>hardware_interface/PositionJointInterface</hardwareInterface></actuator></transmission><gazebo reference="fr3_joint7"><provideFeedback>true</provideFeedback></gazebo><transmission name="fr3_joint7_transmission"><type>transmission_interface/SimpleTransmission</type><joint name="fr3_joint7"><hardwareInterface>hardware_interface/PositionJointInterface</hardwareInterface></joint><actuator name="fr3_joint7_motor"><hardwareInterface>hardware_interface/PositionJointInterface</hardwareInterface></actuator></transmission><gazebo reference="fr3_joint1"><provideFeedback>true</provideFeedback></gazebo><transmission name="fr3_joint1_transmission"><type>transmission_interface/SimpleTransmission</type><joint name="fr3_joint1"><hardwareInterface>hardware_interface/VelocityJointInterface</hardwareInterface></joint><actuator name="fr3_joint1_motor"><hardwareInterface>hardware_interface/VelocityJointInterface</hardwareInterface></actuator></transmission><gazebo reference="fr3_joint2"><provideFeedback>true</provideFeedback></gazebo><transmission name="fr3_joint2_transmission"><type>transmission_interface/SimpleTransmission</type><joint name="fr3_joint2"><hardwareInterface>hardware_interface/VelocityJointInterface</hardwareInterface></joint><actuator name="fr3_joint2_motor"><hardwareInterface>hardware_interface/VelocityJointInterface</hardwareInterface></actuator></transmission><gazebo reference="fr3_joint3"><provideFeedback>true</provideFeedback></gazebo><transmission name="fr3_joint3_transmission"><type>transmission_interface/SimpleTransmission</type><joint name="fr3_joint3"><hardwareInterface>hardware_interface/VelocityJointInterface</hardwareInterface></joint><actuator name="fr3_joint3_motor"><hardwareInterface>hardware_interface/VelocityJointInterface</hardwareInterface></actuator></transmission><gazebo reference="fr3_joint4"><provideFeedback>true</provideFeedback></gazebo><transmission name="fr3_joint4_transmission"><type>transmission_interface/SimpleTransmission</type><joint name="fr3_joint4"><hardwareInterface>hardware_interface/VelocityJointInterface</hardwareInterface></joint><actuator name="fr3_joint4_motor"><hardwareInterface>hardware_interface/VelocityJointInterface</hardwareInterface></actuator></transmission><gazebo reference="fr3_joint5"><provideFeedback>true</provideFeedback></gazebo><transmission name="fr3_joint5_transmission"><type>transmission_interface/SimpleTransmission</type><joint name="fr3_joint5"><hardwareInterface>hardware_interface/VelocityJointInterface</hardwareInterface></joint><actuator name="fr3_joint5_motor"><hardwareInterface>hardware_interface/VelocityJointInterface</hardwareInterface></actuator></transmission><gazebo reference="fr3_joint6"><provideFeedback>true</provideFeedback></gazebo><transmission name="fr3_joint6_transmission"><type>transmission_interface/SimpleTransmission</type><joint name="fr3_joint6"><hardwareInterface>hardware_interface/VelocityJointInterface</hardwareInterface></joint><actuator name="fr3_joint6_motor"><hardwareInterface>hardware_interface/VelocityJointInterface</hardwareInterface></actuator></transmission><gazebo reference="fr3_joint7"><provideFeedback>true</provideFeedback></gazebo><transmission name="fr3_joint7_transmission"><type>transmission_interface/SimpleTransmission</type><joint name="fr3_joint7"><hardwareInterface>hardware_interface/VelocityJointInterface</hardwareInterface></joint><actuator name="fr3_joint7_motor"><hardwareInterface>hardware_interface/VelocityJointInterface</hardwareInterface></actuator></transmission><gazebo reference="fr3_joint1"><provideFeedback>true</provideFeedback></gazebo><transmission name="fr3_joint1_transmission"><type>transmission_interface/SimpleTransmission</type><joint name="fr3_joint1"><hardwareInterface>hardware_interface/EffortJointInterface</hardwareInterface></joint><actuator name="fr3_joint1_motor"><hardwareInterface>hardware_interface/EffortJointInterface</hardwareInterface></actuator></transmission><gazebo reference="fr3_joint2"><provideFeedback>true</provideFeedback></gazebo><transmission name="fr3_joint2_transmission"><type>transmission_interface/SimpleTransmission</type><joint name="fr3_joint2"><hardwareInterface>hardware_interface/EffortJointInterface</hardwareInterface></joint><actuator name="fr3_joint2_motor"><hardwareInterface>hardware_interface/EffortJointInterface</hardwareInterface></actuator></transmission><gazebo reference="fr3_joint3"><provideFeedback>true</provideFeedback></gazebo><transmission name="fr3_joint3_transmission"><type>transmission_interface/SimpleTransmission</type><joint name="fr3_joint3"><hardwareInterface>hardware_interface/EffortJointInterface</hardwareInterface></joint><actuator name="fr3_joint3_motor"><hardwareInterface>hardware_interface/EffortJointInterface</hardwareInterface></actuator></transmission><gazebo reference="fr3_joint4"><provideFeedback>true</provideFeedback></gazebo><transmission name="fr3_joint4_transmission"><type>transmission_interface/SimpleTransmission</type><joint name="fr3_joint4"><hardwareInterface>hardware_interface/EffortJointInterface</hardwareInterface></joint><actuator name="fr3_joint4_motor"><hardwareInterface>hardware_interface/EffortJointInterface</hardwareInterface></actuator></transmission><gazebo reference="fr3_joint5"><provideFeedback>true</provideFeedback></gazebo><transmission name="fr3_joint5_transmission"><type>transmission_interface/SimpleTransmission</type><joint name="fr3_joint5"><hardwareInterface>hardware_interface/EffortJointInterface</hardwareInterface></joint><actuator name="fr3_joint5_motor"><hardwareInterface>hardware_interface/EffortJointInterface</hardwareInterface></actuator></transmission><gazebo reference="fr3_joint6"><provideFeedback>true</provideFeedback></gazebo><transmission name="fr3_joint6_transmission"><type>transmission_interface/SimpleTransmission</type><joint name="fr3_joint6"><hardwareInterface>hardware_interface/EffortJointInterface</hardwareInterface></joint><actuator name="fr3_joint6_motor"><hardwareInterface>hardware_interface/EffortJointInterface</hardwareInterface></actuator></transmission><gazebo reference="fr3_joint7"><provideFeedback>true</provideFeedback></gazebo><transmission name="fr3_joint7_transmission"><type>transmission_interface/SimpleTransmission</type><joint name="fr3_joint7"><hardwareInterface>hardware_interface/EffortJointInterface</hardwareInterface></joint><actuator name="fr3_joint7_motor"><hardwareInterface>hardware_interface/EffortJointInterface</hardwareInterface></actuator></transmission><transmission name="fr3_franka_state"><type>franka_hw/FrankaStateInterface</type><joint name="fr3_joint1"><hardwareInterface>franka_hw/FrankaStateInterface</hardwareInterface></joint><joint name="fr3_joint2"><hardwareInterface>franka_hw/FrankaStateInterface</hardwareInterface></joint><joint name="fr3_joint3"><hardwareInterface>franka_hw/FrankaStateInterface</hardwareInterface></joint><joint name="fr3_joint4"><hardwareInterface>franka_hw/FrankaStateInterface</hardwareInterface></joint><joint name="fr3_joint5"><hardwareInterface>franka_hw/FrankaStateInterface</hardwareInterface></joint><joint name="fr3_joint6"><hardwareInterface>franka_hw/FrankaStateInterface</hardwareInterface></joint><joint name="fr3_joint7"><hardwareInterface>franka_hw/FrankaStateInterface</hardwareInterface></joint><actuator name="fr3_motor1"><hardwareInterface>franka_hw/FrankaStateInterface</hardwareInterface></actuator><actuator name="fr3_motor2"><hardwareInterface>franka_hw/FrankaStateInterface</hardwareInterface></actuator><actuator name="fr3_motor3"><hardwareInterface>franka_hw/FrankaStateInterface</hardwareInterface></actuator><actuator name="fr3_motor4"><hardwareInterface>franka_hw/FrankaStateInterface</hardwareInterface></actuator><actuator name="fr3_motor5"><hardwareInterface>franka_hw/FrankaStateInterface</hardwareInterface></actuator><actuator name="fr3_motor6"><hardwareInterface>franka_hw/FrankaStateInterface</hardwareInterface></actuator><actuator name="fr3_motor7"><hardwareInterface>franka_hw/FrankaStateInterface</hardwareInterface></actuator></transmission><transmission name="fr3_franka_model"><type>franka_hw/FrankaModelInterface</type><joint name="fr3_joint1"><role>root</role><hardwareInterface>franka_hw/FrankaModelInterface</hardwareInterface></joint><joint name="fr3_joint8"><role>tip</role><hardwareInterface>franka_hw/FrankaModelInterface</hardwareInterface></joint><actuator name="fr3_joint1_motor_root"><hardwareInterface>franka_hw/FrankaModelInterface</hardwareInterface></actuator><actuator name="fr3_joint8_motor_tip"><hardwareInterface>franka_hw/FrankaModelInterface</hardwareInterface></actuator></transmission><gazebo reference="fr3_finger_joint1"><provideFeedback>true</provideFeedback></gazebo><transmission name="fr3_finger_joint1_transmission"><type>transmission_interface/SimpleTransmission</type><joint name="fr3_finger_joint1"><hardwareInterface>hardware_interface/EffortJointInterface</hardwareInterface></joint><actuator name="fr3_finger_joint1_motor"><hardwareInterface>hardware_interface/EffortJointInterface</hardwareInterface></actuator></transmission><gazebo reference="fr3_finger_joint2"><provideFeedback>true</provideFeedback></gazebo><transmission name="fr3_finger_joint2_transmission"><type>transmission_interface/SimpleTransmission</type><joint name="fr3_finger_joint2"><hardwareInterface>hardware_interface/EffortJointInterface</hardwareInterface></joint><actuator name="fr3_finger_joint2_motor"><hardwareInterface>hardware_interface/EffortJointInterface</hardwareInterface></actuator></transmission><gazebo reference="fr3_leftfinger"><collision><max_contacts>10</max_contacts><surface><contact><ode><max_vel>0</max_vel><min_depth>0.001</min_depth></ode></contact><friction><ode><mu>1.13</mu><mu2>1.13</mu2></ode></friction><bounce/></surface></collision></gazebo><gazebo reference="fr3_rightfinger"><collision><max_contacts>10</max_contacts><surface><contact><ode><max_vel>0</max_vel><min_depth>0.001</min_depth></ode></contact><friction><ode><mu>1.13</mu><mu2>1.13</mu2></ode></friction><bounce/></surface></collision></gazebo><ros2_control name="GazeboSystem" type="system"><hardware><plugin>ign_ros2_control/IgnitionSystem</plugin></hardware><joint name="fr3_joint1"><command_interface name="position"/><command_interface name="velocity"/><state_interface name="position"><param name="initial_value">0.0</param></state_interface><state_interface name="velocity"/><param name="initial_value">0.0</param><state_interface name="effort"/></joint><joint name="fr3_joint2"><command_interface name="position"/><command_interface name="velocity"/><state_interface name="position"><param name="initial_value">-0.7853981633974483</param></state_interface><state_interface name="velocity"/><param name="initial_value">0.0</param><state_interface name="effort"/></joint><joint name="fr3_joint3"><command_interface name="position"/><command_interface name="velocity"/><state_interface name="position"><param name="initial_value">0.0</param></state_interface><state_interface name="velocity"/><param name="initial_value">0.0</param><state_interface name="effort"/></joint><joint name="fr3_joint4"><command_interface name="position"/><command_interface name="velocity"/><state_interface name="position"><param name="initial_value">-2.356194490192345</param></state_interface><state_interface name="velocity"/><param name="initial_value">0.0</param><state_interface name="effort"/></joint><joint name="fr3_joint5"><command_interface name="position"/><command_interface name="velocity"/><state_interface name="position"><param name="initial_value">0.0</param></state_interface><state_interface name="velocity"/><param name="initial_value">0.0</param><state_interface name="effort"/></joint><joint name="fr3_joint6"><command_interface name="position"/><command_interface name="velocity"/><state_interface name="position"><param name="initial_value">1.5707963267948966</param></state_interface><state_interface name="velocity"/><param name="initial_value">0.0</param><state_interface name="effort"/></joint><joint name="fr3_joint7"><command_interface name="position"/><command_interface name="velocity"/><state_interface name="position"><param name="initial_value">0.7853981633974483</param></state_interface><state_interface name="velocity"/><param name="initial_value">0.0</param><state_interface name="effort"/></joint><joint name="fr3_finger_joint1"><command_interface name="position"/><command_interface name="velocity"/><state_interface name="position"><param name="initial_value">0.0</param></state_interface><state_interface name="velocity"/><param name="initial_value">0.0</param><state_interface name="effort"/></joint></ros2_control><gazebo><plugin filename="libign_ros2_control-system.so" name="ign_ros2_control::IgnitionROS2ControlPlugin"><robot_param>robot_description</robot_param><robot_param_node>robot_state_publisher</robot_param_node><parameters>/root/Gazebo_WS/install/gazebo_practise/share/gazebo_practise/controller_config/controller.yaml</parameters></plugin></gazebo><gazebo reference="fr3_link8_ft_joint"><preserveFixedJoint>true</preserveFixedJoint><sensor name="wrist_ft_sensor" type="force_torque"><always_on>true</always_on><update_rate>1000</update_rate><visualize>true</visualize><topic>/wrist_force_torque</topic><force_torque><frame>child</frame><measure_direction>child_to_parent</measure_direction></force_torque></sensor></gazebo></robot>